(dp1
S'output'
p2
S'<type \'exceptions.RuntimeError\'> Failure to connect, tried 5 times:\nTraceback (most recent call last):\n  File "/var/www/web2py/gluon/packages/dal/pydal/base.py", line 435, in __init__\n    self._adapter = ADAPTERS[self._dbname](**kwargs)\n  File "/var/www/web2py/gluon/packages/dal/pydal/adapters/base.py", line 53, in __call__\n    obj = super(AdapterMeta, cls).__call__(*args, **kwargs)\n  File "/var/www/web2py/gluon/packages/dal/pydal/adapters/postgres.py", line 145, in __init__\n    self.reconnect()\n  File "/var/www/web2py/gluon/packages/dal/pydal/connection.py", line 105, in reconnect\n    self.connection = f()\n  File "/var/www/web2py/gluon/packages/dal/pydal/adapters/postgres.py", line 142, in connector\n    return self.driver.connect(**driver_args)\n  File "/var/www/web2py/gluon/contrib/pg8000/__init__.py", line 336, in connect\n    user, host, unix_sock, port, database, password, ssl)\n  File "/var/www/web2py/gluon/contrib/pg8000/core.py", line 1282, in __init__\n    raise self.error\nProgrammingError: (\'FATAL\', \'3D000\', \'database "teste_ldap" does not exist\')\n'
p3
sS'layer'
p4
S'/var/www/web2py/applications/teste_ldap/models/config.py'
p5
sS'code'
p6
S'# -*- coding: utf-8 -*-\nfrom gluon.storage import Storage\n\nconfig = Storage(\n    db=Storage(),\n)\n\n#Conex\xc3\xa3o com o Banco de Dados\nif request.is_local:\n    config.db.uri = "postgres:pg8000://matheus:123456@localhost/teste_ldap"\nelse:\n    config.db.uri = "postgres:pg8000://forip:yma2578k@127.0.0.1/teste_ldap"\ndb = DAL(**config.db)\n\nfrom gluon.tools import Auth\n\n#Configura\xc3\xa7\xc3\xa3o Auth\nauth = Auth(db, controller="principal",function="login")\nauth.settings.formstyle = "divs"\nauth.settings.login_next = URL(a=\'teste_ldap\', c=\'principal\', f=\'index\')\nauth.settings.remember_me_form = False\nauth.settings.registration_requires_verification = False\nauth.settings.registration_requires_approval = False\nauth.settings.actions_disabled = [\'register\']\nauth.settings.expiration = 3600  # seconds\n\n#Mensagens de Erro \nauth.messages.logged_in = \'Bem Vindo\' \nauth.messages.access_denied = \'Acesso negado! Contate o administrador\'\nauth.messages.invalid_username = \'Usuario Inv\xc3\xa1lido \'\nauth.messages.invalid_login = \'Usuario ou Senha Inv\xc3\xa1lidos\'\nauth.messages.invalid_password = \'Senha Inv\xc3\xa1lida\'\nauth.messages.login_button = "Entrar"\nauth.messages.label_email = \'E-mail\'\nauth.messages.label_password = \'Password\'\n\nauth.define_tables(username=False,signature=False,migrate=True)'
p7
sS'snapshot'
p8
(dp9
sS'traceback'
p10
S'Traceback (most recent call last):\n  File "/var/www/web2py/gluon/restricted.py", line 227, in restricted\n    exec ccode in environment\n  File "/var/www/web2py/applications/teste_ldap/models/config.py", line 13, in <module>\n    db = DAL(**config.db)\n  File "/var/www/web2py/gluon/packages/dal/pydal/base.py", line 171, in __call__\n    obj = super(MetaDAL, cls).__call__(*args, **kwargs)\n  File "/var/www/web2py/gluon/packages/dal/pydal/base.py", line 457, in __init__\n    raise RuntimeError("Failure to connect, tried %d times:\\n%s" % (attempts, tb))\nRuntimeError: Failure to connect, tried 5 times:\nTraceback (most recent call last):\n  File "/var/www/web2py/gluon/packages/dal/pydal/base.py", line 435, in __init__\n    self._adapter = ADAPTERS[self._dbname](**kwargs)\n  File "/var/www/web2py/gluon/packages/dal/pydal/adapters/base.py", line 53, in __call__\n    obj = super(AdapterMeta, cls).__call__(*args, **kwargs)\n  File "/var/www/web2py/gluon/packages/dal/pydal/adapters/postgres.py", line 145, in __init__\n    self.reconnect()\n  File "/var/www/web2py/gluon/packages/dal/pydal/connection.py", line 105, in reconnect\n    self.connection = f()\n  File "/var/www/web2py/gluon/packages/dal/pydal/adapters/postgres.py", line 142, in connector\n    return self.driver.connect(**driver_args)\n  File "/var/www/web2py/gluon/contrib/pg8000/__init__.py", line 336, in connect\n    user, host, unix_sock, port, database, password, ssl)\n  File "/var/www/web2py/gluon/contrib/pg8000/core.py", line 1282, in __init__\n    raise self.error\nProgrammingError: (\'FATAL\', \'3D000\', \'database "teste_ldap" does not exist\')\n\n'
p11
s.